package exceptionTask;

public class exceptionMain {
	
	public static void main(String[] args) {
		
		int c = 0;
		
		try {
			c = 4/0;			
			System.out.println("Done");
			
		}catch(ArithmeticException e) {
			System.out.println("Error Message: " +e.getMessage());
			
			//if Exception is before ArithmeticException then ArithmeticException become unreachable catch block 
			//as situation is already handled by catch block for Exception
			
		}catch(Exception e) {
			System.out.println("Error Message: " +e.getMessage());
		}
		
		
		
		
	}

}
